
# <翻译开始>
func Throw(exception
消息
# <翻译结束>

# <翻译开始>
func Throw
X异常输出
# <翻译结束>

# <翻译开始>
func Try(ctx context.Context, try func(ctx context.Context)) (err
错误
# <翻译结束>

# <翻译开始>
func Try(ctx context.Context, try func(ctx
上下文
# <翻译结束>

# <翻译开始>
func Try(ctx context.Context, try
处理函数
# <翻译结束>

# <翻译开始>
func Try(ctx
上下文
# <翻译结束>

# <翻译开始>
func Try
X异常捕捉
# <翻译结束>

# <翻译开始>
func TryCatch(ctx context.Context, try func(ctx context.Context), catch func(ctx context.Context, exception
错误
# <翻译结束>

# <翻译开始>
func TryCatch(ctx context.Context, try func(ctx context.Context), catch func(ctx
上下文
# <翻译结束>

# <翻译开始>
func TryCatch(ctx context.Context, try func(ctx context.Context), catch
异常处理函数
# <翻译结束>

# <翻译开始>
func TryCatch(ctx context.Context, try func(ctx
上下文
# <翻译结束>

# <翻译开始>
func TryCatch(ctx context.Context, try
处理函数
# <翻译结束>

# <翻译开始>
func TryCatch(ctx
上下文
# <翻译结束>

# <翻译开始>
func TryCatch
X异常捕捉并带异常处理
# <翻译结束>
